W0626 22:10:47.333000 65723 torch/distributed/run.py:766] 
W0626 22:10:47.333000 65723 torch/distributed/run.py:766] *****************************************
W0626 22:10:47.333000 65723 torch/distributed/run.py:766] Setting OMP_NUM_THREADS environment variable for each process to be 1 in default, to avoid your system being overloaded, please further tune the variable for optimal performance in your application as needed. 
W0626 22:10:47.333000 65723 torch/distributed/run.py:766] *****************************************
Traceback (most recent call last):
  File "/home/hslee/FINE-FPN/rtdetrv2_pytorch2/tools/train.py", line 12, in <module>
    from src.solver import TASKS
  File "/home/hslee/FINE-FPN/rtdetrv2_pytorch2/tools/../src/solver/__init__.py", line 4, in <module>
    from ._solver import BaseSolver
  File "/home/hslee/FINE-FPN/rtdetrv2_pytorch2/tools/../src/solver/_solver.py", line 14, in <module>
    from fvcore.nn import FlopCountAnalysis, flop_count_table
ModuleNotFoundError: No module named 'fvcore'
Traceback (most recent call last):
  File "/home/hslee/FINE-FPN/rtdetrv2_pytorch2/tools/train.py", line 12, in <module>
    from src.solver import TASKS
  File "/home/hslee/FINE-FPN/rtdetrv2_pytorch2/tools/../src/solver/__init__.py", line 4, in <module>
    from ._solver import BaseSolver
  File "/home/hslee/FINE-FPN/rtdetrv2_pytorch2/tools/../src/solver/_solver.py", line 14, in <module>
    from fvcore.nn import FlopCountAnalysis, flop_count_table
ModuleNotFoundError: No module named 'fvcore'
Traceback (most recent call last):
  File "/home/hslee/FINE-FPN/rtdetrv2_pytorch2/tools/train.py", line 12, in <module>
    from src.solver import TASKS
  File "/home/hslee/FINE-FPN/rtdetrv2_pytorch2/tools/../src/solver/__init__.py", line 4, in <module>
    from ._solver import BaseSolver
  File "/home/hslee/FINE-FPN/rtdetrv2_pytorch2/tools/../src/solver/_solver.py", line 14, in <module>
    from fvcore.nn import FlopCountAnalysis, flop_count_table
ModuleNotFoundError: No module named 'fvcore'
Traceback (most recent call last):
  File "/home/hslee/FINE-FPN/rtdetrv2_pytorch2/tools/train.py", line 12, in <module>
    from src.solver import TASKS
  File "/home/hslee/FINE-FPN/rtdetrv2_pytorch2/tools/../src/solver/__init__.py", line 4, in <module>
    from ._solver import BaseSolver
  File "/home/hslee/FINE-FPN/rtdetrv2_pytorch2/tools/../src/solver/_solver.py", line 14, in <module>
    from fvcore.nn import FlopCountAnalysis, flop_count_table
ModuleNotFoundError: No module named 'fvcore'
E0626 22:10:49.541000 65723 torch/distributed/elastic/multiprocessing/api.py:874] failed (exitcode: 1) local_rank: 0 (pid: 65789) of binary: /home/hslee/myenv/bin/python3
Traceback (most recent call last):
  File "/home/hslee/myenv/bin/torchrun", line 8, in <module>
    sys.exit(main())
             ^^^^^^
  File "/home/hslee/myenv/lib/python3.12/site-packages/torch/distributed/elastic/multiprocessing/errors/__init__.py", line 355, in wrapper
    return f(*args, **kwargs)
           ^^^^^^^^^^^^^^^^^^
  File "/home/hslee/myenv/lib/python3.12/site-packages/torch/distributed/run.py", line 892, in main
    run(args)
  File "/home/hslee/myenv/lib/python3.12/site-packages/torch/distributed/run.py", line 883, in run
    elastic_launch(
  File "/home/hslee/myenv/lib/python3.12/site-packages/torch/distributed/launcher/api.py", line 139, in __call__
    return launch_agent(self._config, self._entrypoint, list(args))
           ^^^^^^^^^^^^^^^^^^^^^^^^^^^^^^^^^^^^^^^^^^^^^^^^^^^^^^^^
  File "/home/hslee/myenv/lib/python3.12/site-packages/torch/distributed/launcher/api.py", line 270, in launch_agent
    raise ChildFailedError(
torch.distributed.elastic.multiprocessing.errors.ChildFailedError: 
============================================================
tools/train.py FAILED
------------------------------------------------------------
Failures:
[1]:
  time      : 2025-06-26_22:10:49
  host      : black
  rank      : 1 (local_rank: 1)
  exitcode  : 1 (pid: 65790)
  error_file: <N/A>
  traceback : To enable traceback see: https://pytorch.org/docs/stable/elastic/errors.html
[2]:
  time      : 2025-06-26_22:10:49
  host      : black
  rank      : 2 (local_rank: 2)
  exitcode  : 1 (pid: 65791)
  error_file: <N/A>
  traceback : To enable traceback see: https://pytorch.org/docs/stable/elastic/errors.html
[3]:
  time      : 2025-06-26_22:10:49
  host      : black
  rank      : 3 (local_rank: 3)
  exitcode  : 1 (pid: 65792)
  error_file: <N/A>
  traceback : To enable traceback see: https://pytorch.org/docs/stable/elastic/errors.html
------------------------------------------------------------
Root Cause (first observed failure):
[0]:
  time      : 2025-06-26_22:10:49
  host      : black
  rank      : 0 (local_rank: 0)
  exitcode  : 1 (pid: 65789)
  error_file: <N/A>
  traceback : To enable traceback see: https://pytorch.org/docs/stable/elastic/errors.html
============================================================
